Workbook
Name UPDATE: 'Data Sheet'!$E$1

Sheet Three Statement Model
A1: TITAN (Three Statement Model) | D1: Historical Results | I1: Forecast Period
D2: 2021 | E2: =D2+1 -> 2022 | F2: =E2+1 -> 2023 | G2: =F2+1 -> 2024 | H2: =G2+1 -> 2025 | I2: =H2+1 -> 2026 | J2: =I2+1 -> 2027 | K2: =J2+1 -> 2028 | L2: =K2+1 -> 2029 | M2: =L2+1 -> 2030
A4: Assumptions
A6: Key Assumptions
A7: Revenue Growth (% Change) | E7: =E25/D25-1 -> 0.3305766 | F7: =F25/E25-1 -> 0.40890309 | G7: =G25/F25-1 -> 0.25900185 | H7: =H25/G25-1 -> 0.18346253 | I7: 0.12 | J7: 0.14 | K7: 0.13 | L7: 0.15 | M7: 0.15
A8: Cost of Goods Sold (% of Revenue) | D8: =D26/D25 -> 0.75531325 | E8: =E26/E25 -> 1.0923643 | F8: =F26/F25 -> 0.86523722 | G8: =G26/G25 -> 0.88346645 | H8: =H26/H25 -> 1.0501853 | I8: 0.8 | J8: 0.8 | K8: 0.82 | L8: 0.84 | M8: 0.85
A9: Salaries and Benefits (% of Revenue) | D9: =D29/D25 -> 0.049390131 | E9: =E29/E25 -> 0.047084968 | F9: =F29/F25 -> 0.040813309 | G9: =G29/G25 -> 0.036704252 | H9: =H29/H25 -> 0.035794627 | I9: =(D9+E9+F9+G9+H9)/5 -> 0.041957457 | J9: =(E9+F9+G9+H9+I9)/5 -> 0.040470923 | K9: =(F9+G9+H9+I9+J9)/5 -> 0.039148114 | L9: =(G9+H9+I9+J9+K9)/5 -> 0.038815075 | M9: =(H9+I9+J9+K9+L9)/5 -> 0.039237239
A10: Rent and Overhead | D10: =D30 -> 1229 | E10: =E30 -> 533 | F10: =F30 -> 683 | G10: =G30 -> 879 | H10: =H30 -> 1250 | I10: =(D10+E10+F10+G10+H10)/5 -> 914.8 | J10: =(E10+F10+G10+H10+I10)/5 -> 851.96 | K10: =(F10+G10+H10+I10+J10)/5 -> 915.752 | L10: =(G10+H10+I10+J10+K10)/5 -> 962.3024 | M10: =(H10+I10+J10+K10+L10)/5 -> 978.96288
A11: Depreciation & Amortization (% of PP&E) | D11: =D31/D46 -> 0.14863258 | E11: =E31/E46 -> 0.15683962 | F11: =F31/F46 -> 0.14709807 | G11: =G31/G46 -> 0.15745484 | H11: =H31/H46 -> 0.17060561 | I11: =(D11+E11+F11+G11+H11)/5 -> 0.15612614 | J11: =(E11+F11+G11+H11+I11)/5 -> 0.15762486 | K11: =(F11+G11+H11+I11+J11)/5 -> 0.1577819 | L11: =(G11+H11+I11+J11+K11)/5 -> 0.15991867 | M11: =(H11+I11+J11+K11+L11)/5 -> 0.16041144
A12: Interest (% of Debt) | D12: =D32/D51 -> 0.036005676 | E12: =E32/E51 -> 0.029965636 | F12: =F32/F51 -> 0.03202733 | G12: =G32/G51 -> 0.039863472 | H12: =H32/H51 -> 0.045868027 | I12: =(D12+E12+F12+G12+H12)/5 -> 0.036746028 | J12: =(E12+F12+G12+H12+I12)/5 -> 0.036894099 | K12: =(F12+G12+H12+I12+J12)/5 -> 0.038279791 | L12: =(G12+H12+I12+J12+K12)/5 -> 0.039530284 | M12: =(H12+I12+J12+K12+L12)/5 -> 0.039463646
A13: Tax Rate (% of Earnings Before Tax) | D13: =D36/D34 -> 0.14586777 | E13: =E36/E34 -> -0.1366628 | F13: =F36/F34 -> 0.49120603 | G13: =G36/G34 -> 0.56462926 | H13: =H36/H34 -> -0.14801087 | I13: 0.25 | J13: 0.25 | K13: 0.25 | L13: 0.25 | M13: 0.25
A14: Accounts Receivable (Days) | D14: =D44/D25*365 -> 6.1721493 | E14: =E44/E25*365 -> 7.1608389 | F14: =F44/F25*365 -> 6.063093 | G14: =G44/G25*365 -> 7.2737061 | H14: =H44/H25*365 -> 6.4479952 | I14: 6 | J14: 6 | K14: 6 | L14: 6 | M14: 6
A15: Inventory (Days) | D15: =D45/D26*365 -> 187.72449 | E15: =E45/E26*365 -> 157.8971 | F15: =F45/F26*365 -> 172.42032 | G15: =G45/G26*365 -> 154.07624 | H15: =H45/H26*365 -> 162.02804 | I15: 162 | J15: 152 | K15: 142 | L15: 134 | M15: 110
A16: Accounts Payable (Days) | D16: =D50/D26*365 -> 73.879679 | E16: =E50/E26*365 -> 53.487078 | F16: =F50/F26*365 -> 60.322158 | G16: =G50/G26*365 -> 53.588221 | H16: =H50/H26*365 -> 47.394235 | I16: 47 | J16: 47 | K16: 50 | L16: 47 | M16: 47
A17: Capital Expenditures | D17: =D71 -> 106 | E17: =E71 -> 38 | F17: =F71 -> 13 | G17: =G71 -> 177 | H17: =H71 -> -2 | I17: 13 | J17: 54 | K17: 142 | L17: 114 | M17: 40
A18: Debt Issuance (Repayment) | D18: =D75 -> 0 | E18: =E75 -> 0 | F18: =F75 -> 0 | G18: =G75 -> 0 | H18: =H75 -> 0
A19: Equity Issued (Repaid) | D19: =D76 -> 0 | E19: =E76 -> 0 | F19: =F76 -> 0 | G19: =G76 -> 0 | H19: =H76 -> 0
A20: Days in Period | D20: 365 | E20: 365 | F20: 365 | G20: 365 | H20: 365 | I20: 365 | J20: 365 | K20: 365 | L20: 365 | M20: 365
A23: Income Statement
A25: Revenue | D25: =IFERROR('Profit & Loss '!G4,0) -> 21644 | E25: =IFERROR('Profit & Loss '!H4,0) -> 28799 | F25: =IFERROR('Profit & Loss '!I4,0) -> 40575 | G25: =IFERROR('Profit & Loss '!J4,0) -> 51084 | H25: =IFERROR('Profit & Loss '!K4,0) -> 60456 | I25: =H25*(1+I7) -> 67710.72 | J25: =I25*(1+J7) -> 77190.221 | K25: =J25*(1+K7) -> 87224.95 | L25: =K25*(1+L7) -> 100308.69 | M25: =L25*(1+M7) -> 115355
A26: Cost of Goods Sold (COGS) | D26: =IFERROR('Data Sheet'!G18+'Data Sheet'!G19+'Data Sheet'!G21+'Data Sheet'!G20,0) -> 16348 | E26: =IFERROR('Data Sheet'!H18+'Data Sheet'!H19+'Data Sheet'!H21+'Data Sheet'!H20,0) -> 31459 | F26: =IFERROR('Data Sheet'!I18+'Data Sheet'!I19+'Data Sheet'!I21+'Data Sheet'!I20,0) -> 35107 | G26: =IFERROR('Data Sheet'!J18+'Data Sheet'!J19+'Data Sheet'!J21+'Data Sheet'!J20,0) -> 45131 | H26: =IFERROR('Data Sheet'!K18+'Data Sheet'!K19+'Data Sheet'!K21+'Data Sheet'!K20,0) -> 63490 | I26: =I25*I8 -> 54168.576 | J26: =J25*J8 -> 61752.177 | K26: =K25*K8 -> 71524.459 | L26: =L25*L8 -> 84259.301 | M26: =M25*M8 -> 98051.746
A27: Gross Profit | D27: =D25-D26 -> 5296 | E27: =E25-E26 -> -2660 | F27: =F25-F26 -> 5468 | G27: =G25-G26 -> 5953 | H27: =H25-H26 -> -3034 | I27: =I25-I26 -> 13542.144 | J27: =J25-J26 -> 15438.044 | K27: =K25-K26 -> 15700.491 | ... M27: =M25-M26 -> 17303.249
A28: Expenses
A29: Salaries and Benefits | D29: =IFERROR('Data Sheet'!G22,0) -> 1069 | E29: =IFERROR('Data Sheet'!H22,0) -> 1356 | F29: =IFERROR('Data Sheet'!I22,0) -> 1656 | G29: =IFERROR('Data Sheet'!J22,0) -> 1875 | H29: =IFERROR('Data Sheet'!K22,0) -> 2164 | I29: =I9*I25 -> 2840.9697 | J29: =J9*J25 -> 3123.9595 | K29: =K9*K25 -> 3414.6922 | L29: =L9*L25 -> 3893.4894 | M29: =M9*M25 -> 4526.2116
A30: Rent and Overhead | D30: =IFERROR('Data Sheet'!G24,0) -> 1229 | E30: =IFERROR('Data Sheet'!H24,0) -> 533 | F30: =IFERROR('Data Sheet'!I24,0) -> 683 | G30: =IFERROR('Data Sheet'!J24,0) -> 879 | H30: =IFERROR('Data Sheet'!K24,0) -> 1250 | I30: =I10 -> 914.8 | J30: =J10 -> 851.96 | K30: =K10 -> 915.752 | L30: =L10 -> 962.3024 | M30: =M10 -> 978.96288
A31: Depreciation & Amortization | D31: =IFERROR('Profit & Loss '!G8,0) -> 375 | E31: =IFERROR('Profit & Loss '!H8,0) -> 399 | F31: =IFERROR('Profit & Loss '!I8,0) -> 441 | G31: =IFERROR('Profit & Loss '!J8,0) -> 584 | H31: =IFERROR('Profit & Loss '!K8,0) -> 693 | I31: =I66 -> 534.41979 | J31: =J66 -> 457.36117 | K31: =K66 -> 394.17376 | L31: =L66 -> 359.18458 | M31: =M66 -> 320.96094
A32: Interest | D32: =IFERROR('Profit & Loss '!G9,0) -> 203 | E32: =IFERROR('Profit & Loss '!H9,0) -> 218 | F32: =IFERROR('Profit & Loss '!I9,0) -> 300 | G32: =IFERROR('Profit & Loss '!J9,0) -> 619 | H32: =IFERROR('Profit & Loss '!K9,0) -> 953 | I32: =I104 -> 36.746028 | J32: =J104 -> 36.894099 | K32: =K104 -> 38.279791 | L32: =L104 -> 39.530284 | M32: =M104 -> 39.463646
A33: Total Expenses | D33: =SUM(D29:D32) -> 2876 | E33: =SUM(E29:E32) -> 2506 | F33: =SUM(F29:F32) -> 3080 | G33: =SUM(G29:G32) -> 3957 | H33: =SUM(H29:H32) -> 5060 | I33: =SUM(I29:I32) -> 4326.9355 | J33: =SUM(J29:J32) -> 4470.1747 | K33: =SUM(K29:K32) -> 4762.8978 | ... M33: =SUM(M29:M32) -> 5865.599
A34: Earnings Before Tax | D34: =D27-D33 -> 2420 | E34: =E27-E33 -> -5166 | F34: =F27-F33 -> 2388 | G34: =G27-G33 -> 1996 | H34: =H27-H33 -> -8094 | I34: =I27-I33 -> 9215.2085 | J34: =J27-J33 -> 10967.869 | K34: =K27-K33 -> 10937.593 | ... M34: =M27-M33 -> 11437.65
A36: Taxes | D36: =IFERROR('Profit & Loss '!G11,0) -> 353 | E36: =IFERROR('Profit & Loss '!H11,0) -> 706 | F36: =IFERROR('Profit & Loss '!I11,0) -> 1173 | G36: =IFERROR('Profit & Loss '!J11,0) -> 1127 | H36: =IFERROR('Profit & Loss '!K11,0) -> 1198 | I36: =I34*I13 -> 2303.8021 | J36: =J34*J13 -> 2741.9674 | K36: =K34*K13 -> 2734.3983 | L36: =L34*L13 -> 2698.721 | M36: =M34*M13 -> 2859.4126
A37: Net Earnings | D37: =D34-D36 -> 2067 | E37: =E34-E36 -> -5872 | F37: =F34-F36 -> 1215 | G37: =G34-G36 -> 869 | H37: =H34-H36 -> -9292 | I37: =I34-I36 -> 6911.4064 | J37: =J34-J36 -> 8225.9021 | K37: =K34-K36 -> 8203.1948 | ... M37: =M34-M36 -> 8578.2377
A40: Balance Sheet
A42: Assets
A43: Cash | D43: =IFERROR('Data Sheet'!G69,0) -> 560 | E43: =IFERROR('Data Sheet'!H69,0) -> 1573 | F43: =IFERROR('Data Sheet'!I69,0) -> 1343 | G43: =IFERROR('Data Sheet'!J69,0) -> 1526 | H43: =IFERROR('Data Sheet'!K69,0) -> 1584 | I43: =I81 -> 12444.962 | J43: =J81 -> 20220.884 | K43: =K81 -> 28247.541 | L43: =L81 -> 34318.172 | M43: =M81 -> 46089.758
A44: Accounts Receivable | D44: =IFERROR('Data Sheet'!G67,0) -> 366 | E44: =IFERROR('Data Sheet'!H67,0) -> 565 | F44: =IFERROR('Data Sheet'!I67,0) -> 674 | G44: =IFERROR('Data Sheet'!J67,0) -> 1018 | H44: =IFERROR('Data Sheet'!K67,0) -> 1068 | I44: =I25*I14/I20 -> 1113.0529 | J44: =J25*J14/J20 -> 1268.8803 | K44: =K25*K14/K20 -> 1433.8348 | L44: =L25*L14/L20 -> 1648.91 | M44: =M25*M14/M20 -> 1896.2465
A45: Inventory | D45: =IFERROR('Data Sheet'!G68,0) -> 8408 | E45: =IFERROR('Data Sheet'!H68,0) -> 13609 | F45: =IFERROR('Data Sheet'!I68,0) -> 16584 | G45: =IFERROR('Data Sheet'!J68,0) -> 19051 | H45: =IFERROR('Data Sheet'!K68,0) -> 28184 | I45: =I26*I15/I20 -> 24041.943 | J45: =J26*J15/J20 -> 25715.975 | K45: =K26*K15/K20 -> 27825.954 | L45: =L26*L15/L20 -> 30933.552 | M45: =M26*M15/M20 -> 29549.841
A46: Property & Equipment | D46: =IFERROR('Data Sheet'!G62,0) -> 2523 | E46: =IFERROR('Data Sheet'!H62,0) -> 2544 | F46: =IFERROR('Data Sheet'!I62,0) -> 2998 | G46: =IFERROR('Data Sheet'!J62,0) -> 3709 | H46: =IFERROR('Data Sheet'!K62,0) -> 4062 | I46: =I98 -> 2901.5802 | J46: =J98 -> 2498.219 | K46: =K98 -> 2246.0453 | L46: =L98 -> 2000.8607 | M46: =M98 -> 1719.8998
A47: Total Assets | D47: =SUM(D43:D46) -> 11857 | E47: =SUM(E43:E46) -> 18291 | F47: =SUM(F43:F46) -> 21599 | G47: =SUM(G43:G46) -> 25304 | H47: =SUM(H43:H46) -> 34898 | I47: =SUM(I43:I46) -> 40501.538 | J47: =SUM(J43:J46) -> 49703.959 | K47: =SUM(K43:K46) -> 59753.374 | ... M47: =SUM(M43:M46) -> 79255.745
A49: Liabilities
A50: Accounts Payable | D50: =IFERROR('Data Sheet'!G60,0) -> 3309 | E50: =IFERROR('Data Sheet'!H60,0) -> 4610 | F50: =IFERROR('Data Sheet'!I60,0) -> 5802 | G50: =IFERROR('Data Sheet'!J60,0) -> 6626 | H50: =IFERROR('Data Sheet'!K60,0) -> 8244 | I50: =I26*I16/I20 -> 6975.1317 | J50: =J26*J16/J20 -> 7951.6501 | K50: =K26*K16/K20 -> 9797.871 | L50: =L26*L16/L20 -> 10849.828 | M50: =M26*M16/M20 -> 12625.841
...

Sheet Data>>

Sheet Data Sheet
A1: COMPANY NAME | B1: TITAN COMPANY LTD | E1: =IF(B2<>B3, "A NEW VERSION OF THE WORKSHEET IS AVAILABLE", "")
A2: LATEST VERSION | B2: 2.1 | E2: PLEASE DO NOT MAKE ANY CHANGES TO THIS SHEET
A3: CURRENT VERSION | B3: 2.1
A5: META
A6: Number of shares | B6: =IF(B9>0, B9/B8, 0) -> 88.734027
A7: Face Value | B7: 1
A8: Current Price | B8: 4181.1
A9: Market Capitalization | B9: 371005.84
A15: PROFIT & LOSS
A16: Report Date | B16: 42460 | C16: 42825 | D16: 43190 | E16: 43555 | F16: 43921 | G16: 44286 | H16: 44651 | I16: 45016 | J16: 45382 | K16: 45747
A17: Sales | B17: 11275.89 | C17: 13260.83 | D17: 16119.77 | E17: 19778.52 | F17: 21052 | G17: 21644 | H17: 28799 | I17: 40575 | J17: 51084 | K17: 60456
A18: Raw Material Cost | B18: 8372.17 | C18: 9821.14 | D18: 12664.83 | E18: 15170.66 | F18: 16033 | G18: 16292 | H18: 26436 | I18: 32589 | J18: 42103 | K18: 55271
A19: Change in Inventory | B19: 191.43 | C19: 313.71 | D19: 978.61 | E19: 776.41 | F19: 878 | G19: -122 | H19: 4795 | I19: 2234 | J19: 2671 | K19: 7815
A20: Power and Fuel | B20: 41.2 | C20: 43.84 | D20: 45.32 | E20: 48.51 | F20: 52 | G20: 37 | H20: 45 | I20: 59 | J20: 71 | K20: 78
A21: Other Mfr. Exp | B21: 261.7 | C21: 160.42 | D21: 124.83 | E21: 193.28 | F21: 215 | G21: 141 | H21: 183 | I21: 225 | J21: 286 | K21: 326
A22: Employee Cost | B22: 699.69 | C22: 894.32 | D22: 906.26 | E22: 1024.44 | F22: 1204 | G22: 1069 | H22: 1356 | I22: 1656 | J22: 1875 | K22: 2164
A23: Selling and admin | B23: 846.43 | C23: 1211.16 | D23: 1277.81 | E23: 1454.32 | F23: 1470 | G23: 1029 | H23: 1697 | I23: 2715 | J23: 3249 | K23: 3488
A24: Other Expenses | B24: 306.8 | C24: 279.76 | D24: 435.13 | E24: 669.93 | F24: 493 | G24: 1229 | H24: 533 | I24: 683 | J24: 879 | K24: 1250
A25: Other Income | B25: 69.33 | C25: -42.38 | D25: 69.93 | E25: 178.48 | F25: 153 | G25: 180 | H25: 177 | I25: 306 | J25: 534 | K25: 487
A26: Depreciation | B26: 98.19 | C26: 110.53 | D26: 131.43 | E26: 162.84 | F26: 348 | G26: 375 | H26: 399 | I26: 441 | J26: 584 | K26: 693
A27: Interest | B27: 42.36 | C27: 37.74 | D27: 52.92 | E27: 52.54 | F27: 166 | G27: 203 | H27: 218 | I27: 300 | J27: 619 | K27: 953
... A31: Dividend Amount | B31: 195.32 | C31: 230.83 | D31: 332.92 | E31: 443.9 | F31: 356 | G31: 356 | H31: 667.5 | I31: 890 | J31: 979 | K31: 979
A40: Quarters
A41: Report Date | B41: 45199 | C41: 45291 | D41: 45382 | E41: 45473 | F41: 45565 | G41: 45657 | H41: 45747 | I41: 45838 | J41: 45930 | K41: 46022
A42: Sales | B42: 12529 | C42: 14164 | D42: 12494 | E42: 13266 | F42: 14534 | G42: 17740 | H42: 14916 | I42: 16523 | J42: 18725 | K42: 25416
A43: Expenses | B43: 11118 | C43: 12599 | D43: 11303 | E43: 12019 | F43: 13298 | G43: 16066 | H43: 13379 | I43: 14693 | J43: 16850 | K43: 22703
A44: Other Income | B44: 125 | C44: 136 | D44: 159 | E44: 120 | F44: 123 | G44: 128 | H44: 116 | I44: 105 | J44: 113 | K44: -1
A45: Depreciation | B45: 144 | C45: 154 | D45: 158 | E45: 164 | F45: 171 | G45: 175 | H45: 183 | I45: 184 | J45: 189 | K45: 207
A46: Interest | B46: 140 | C46: 169 | D46: 201 | E46: 230 | F46: 240 | G46: 231 | H46: 252 | I46: 271 | J46: 277 | K46: 282
A47: Profit before tax | B47: 1252 | C47: 1378 | D47: 991 | E47: 973 | F47: 948 | G47: 1396 | H47: 1218 | I47: 1480 | J47: 1522 | K47: 2223
A48: Tax | B48: 336 | C48: 325 | D48: 220 | E48: 258 | F48: 244 | G48: 349 | H48: 347 | I48: 389 | J48: 402 | K48: 539
A49: Net profit | B49: 915 | C49: 1053 | D49: 771 | E49: 715 | F49: 704 | G49: 1047 | H49: 871 | I49: 1091 | J49: 1120 | K49: 1684
A50: Operating Profit | B50: 1411 | C50: 1565 | D50: 1191 | E50: 1247 | F50: 1236 | G50: 1674 | H50: 1537 | I50: 1830 | J50: 1875 | K50: 2713
A55: BALANCE SHEET
A56: Report Date | B56: 42460 | C56: 42825 | D56: 43190 | E56: 43555 | F56: 43921 | G56: 44286 | H56: 44651 | I56: 45016 | J56: 45382 | K56: 45747
A57: Equity Share Capital | B57: 88.78 | C57: 88.78 | D57: 88.78 | E57: 88.78 | F57: 89 | G57: 89 | H57: 89 | I57: 89 | J57: 89 | K57: 89
A58: Reserves | B58: 3417.5 | C58: 4143.6 | D58: 5001.1 | E58: 5981.37 | F58: 6580 | G58: 7408 | H58: 9214 | I58: 11762 | J58: 9304 | K58: 11535
A59: Borrowings | B59: 113.05 | C59: 1882.43 | D59: 1691.01 | E59: 2392.98 | F59: 3562 | G59: 5638 | H59: 7275 | I59: 9367 | J59: 15528 | K59: 20777
A60: Other Liabilities | B60: 2722.58 | C60: 2292.76 | D60: 2740.15 | E60: 3246.71 | F60: 3313 | G60: 3309 | H60: 4610 | I60: 5802 | J60: 6626 | K60: 8244
A61: Total | B61: 6341.91 | C61: 8407.57 | D61: 9521.04 | E61: 11709.84 | F61: 13544 | G61: 16444 | H61: 21188 | I61: 27020 | J61: 31547 | K61: 40645
...

Sheet Profit & Loss 
A1: ='Data Sheet'!B1 -> TITAN COMPANY LTD | H1: =UPDATE | M1: SCREENER.IN
A3: Narration | B3: ='Data Sheet'!B16 -> 42460 | C3: ='Data Sheet'!C16 -> 42825 | D3: ='Data Sheet'!D16 -> 43190 | E3: ='Data Sheet'!E16 -> 43555 | F3: ='Data Sheet'!F16 -> 43921 | G3: ='Data Sheet'!G16 -> 44286 | H3: ='Data Sheet'!H16 -> 44651 | I3: ='Data Sheet'!I16 -> 45016 | ... K3: ='Data Sheet'!K16 -> 45747 | L3: Trailing | M3: Best Case | N3: Worst Case
A4: Sales | B4: ='Data Sheet'!B17 -> 11275.89 | C4: ='Data Sheet'!C17 -> 13260.83 | D4: ='Data Sheet'!D17 -> 16119.77 | E4: ='Data Sheet'!E17 -> 19778.52 | F4: ='Data Sheet'!F17 -> 21052 | G4: ='Data Sheet'!G17 -> 21644 | H4: ='Data Sheet'!H17 -> 28799 | I4: ='Data Sheet'!I17 -> 40575 | ... K4: ='Data Sheet'!K17 -> 60456 | L4: =SUM(Quarters!H4:K4) -> 75580 | M4: =$K4+M23*K4 -> 77409.348 | N4: =$K4+N23*L4 -> 75959.341
A5: Expenses | B5: =SUM('Data Sheet'!B18,'Data Sheet'!B20:B24, -1*'Data Sheet'!B19) -> 10336.56 | C5: =SUM('Data Sheet'!C18,'Data Sheet'!C20:C24, -1*'Data Sheet'!C19) -> 12096.93 | D5: =SUM('Data Sheet'!D18,'Data Sheet'!D20:D24, -1*'Data Sheet'!D19) -> 14475.57 | E5: =SUM('Data Sheet'!E18,'Data Sheet'!E20:E24, -1*'Data Sheet'!E19) -> 17784.73 | F5: =SUM('Data Sheet'!F18,'Data Sheet'!F20:F24, -1*'Data Sheet'!F19) -> 18589 | G5: =SUM('Data Sheet'!G18,'Data Sheet'!G20:G24, -1*'Data Sheet'!G19) -> 19919 | H5: =SUM('Data Sheet'!H18,'Data Sheet'!H20:H24, -1*'Data Sheet'!H19) -> 25455 | I5: =SUM('Data Sheet'!I18,'Data Sheet'!I20:I24, -1*'Data Sheet'!I19) -> 35693 | ... K5: =SUM('Data Sheet'!K18,'Data Sheet'!K20:K24, -1*'Data Sheet'!K19) -> 54762 | L5: =SUM(Quarters!H5:K5) -> 67625 | M5: =M4-M6 -> 69261.804 | N5: =N4-N6 -> 68166.393
A6: Operating Profit | B6: =B4-B5 -> 939.33 | C6: =C4-C5 -> 1163.9 | D6: =D4-D5 -> 1644.2 | E6: =E4-E5 -> 1993.79 | F6: =F4-F5 -> 2463 | G6: =G4-G5 -> 1725 | H6: =H4-H5 -> 3344 | I6: =I4-I5 -> 4882 | ... K6: =K4-K5 -> 5694 | L6: =SUM(Quarters!H6:K6) -> 7955 | M6: =M4*M24 -> 8147.5438 | N6: =N4*N24 -> 7792.9475
A7: Other Income | B7: ='Data Sheet'!B25 -> 69.33 | C7: ='Data Sheet'!C25 -> -42.38 | D7: ='Data Sheet'!D25 -> 69.93 | E7: ='Data Sheet'!E25 -> 178.48 | F7: ='Data Sheet'!F25 -> 153 | G7: ='Data Sheet'!G25 -> 180 | H7: ='Data Sheet'!H25 -> 177 | I7: ='Data Sheet'!I25 -> 306 | ... K7: ='Data Sheet'!K25 -> 487 | L7: =SUM(Quarters!H7:K7) -> 333 | M7: 0 | N7: 0
A8: Depreciation | B8: ='Data Sheet'!B26 -> 98.19 | C8: ='Data Sheet'!C26 -> 110.53 | D8: ='Data Sheet'!D26 -> 131.43 | E8: ='Data Sheet'!E26 -> 162.84 | F8: ='Data Sheet'!F26 -> 348 | G8: ='Data Sheet'!G26 -> 375 | H8: ='Data Sheet'!H26 -> 399 | I8: ='Data Sheet'!I26 -> 441 | ... K8: ='Data Sheet'!K26 -> 693 | L8: =SUM(Quarters!H8:K8) -> 763 | M8: =+$L8 -> 763 | N8: =+$L8 -> 763
A9: Interest | B9: ='Data Sheet'!B27 -> 42.36 | C9: ='Data Sheet'!C27 -> 37.74 | D9: ='Data Sheet'!D27 -> 52.92 | E9: ='Data Sheet'!E27 -> 52.54 | F9: ='Data Sheet'!F27 -> 166 | G9: ='Data Sheet'!G27 -> 203 | H9: ='Data Sheet'!H27 -> 218 | I9: ='Data Sheet'!I27 -> 300 | ... K9: ='Data Sheet'!K27 -> 953 | L9: =SUM(Quarters!H9:K9) -> 1082 | M9: =+$L9 -> 1082 | N9: =+$L9 -> 1082
A10: Profit before tax | B10: ='Data Sheet'!B28 -> 868.11 | C10: ='Data Sheet'!C28 -> 973.25 | D10: ='Data Sheet'!D28 -> 1529.78 | E10: ='Data Sheet'!E28 -> 1956.89 | F10: ='Data Sheet'!F28 -> 2102 | G10: ='Data Sheet'!G28 -> 1327 | H10: ='Data Sheet'!H28 -> 2904 | I10: ='Data Sheet'!I28 -> 4447 | ... K10: ='Data Sheet'!K28 -> 4535 | L10: =SUM(Quarters!H10:K10) -> 6443 | M10: =M6+M7-SUM(M8:M9) -> 6302.5438 | N10: =N6+N7-SUM(N8:N9) -> 5947.9475
A11: Tax | B11: ='Data Sheet'!B29 -> 191.59 | C11: ='Data Sheet'!C29 -> 275.97 | D11: ='Data Sheet'!D29 -> 427.87 | E11: ='Data Sheet'!E29 -> 568.24 | F11: ='Data Sheet'!F29 -> 609 | G11: ='Data Sheet'!G29 -> 353 | H11: ='Data Sheet'!H29 -> 706 | I11: ='Data Sheet'!I29 -> 1173 | ... K11: ='Data Sheet'!K29 -> 1198 | L11: =SUM(Quarters!H11:K11) -> 1677 | M11: =IF($L10>0,$L11/$L10,0) -> 0.26028248 | N11: =IF($L10>0,$L11/$L10,0) -> 0.26028248
A12: Net profit | B12: ='Data Sheet'!B30 -> 674.52 | C12: ='Data Sheet'!C30 -> 711.47 | D12: ='Data Sheet'!D30 -> 1130.09 | E12: ='Data Sheet'!E30 -> 1404.15 | F12: ='Data Sheet'!F30 -> 1501 | G12: ='Data Sheet'!G30 -> 973 | H12: ='Data Sheet'!H30 -> 2173 | I12: ='Data Sheet'!I30 -> 3250 | ... K12: ='Data Sheet'!K30 -> 3337 | L12: =SUM(Quarters!H12:K12) -> 4766 | M12: =M10-M11*M10 -> 4662.1021 | N12: =N10-N11*N10 -> 4399.801
A13: EPS | B13: =IF('Data Sheet'!B93>0,B12/'Data Sheet'!B93,0) -> 7.5976571 | C13: =IF('Data Sheet'!C93>0,C12/'Data Sheet'!C93,0) -> 8.0138545 | D13: =IF('Data Sheet'!D93>0,D12/'Data Sheet'!D93,0) -> 12.729106 | E13: =IF('Data Sheet'!E93>0,E12/'Data Sheet'!E93,0) -> 15.816062 | F13: =IF('Data Sheet'!F93>0,F12/'Data Sheet'!F93,0) -> 16.906961 | G13: =IF('Data Sheet'!G93>0,G12/'Data Sheet'!G93,0) -> 10.959676 | H13: =IF('Data Sheet'!H93>0,H12/'Data Sheet'!H93,0) -> 24.476233 | I13: =IF('Data Sheet'!I93>0,I12/'Data Sheet'!I93,0) -> 36.607344 | ... K13: =IF('Data Sheet'!K93>0,K12/'Data Sheet'!K93,0) -> 37.587294 | L13: =IF('Data Sheet'!$B6>0,'Profit & Loss '!L12/'Data Sheet'!$B6,0) -> 53.711075 | M13: =IF('Data Sheet'!$B6>0,'Profit & Loss '!M12/'Data Sheet'!$B6,0) -> 52.540184 | N13: =IF('Data Sheet'!$B6>0,'Profit & Loss '!N12/'Data Sheet'!$B6,0) -> 49.584147
A14: Price to earning | B14: =IF(B15>0,B15/B13,"") -> 44.592694 | C14: =IF(C15>0,C15/C13,"") -> 57.743749 | D14: =IF(D15>0,D15/D13,"") -> 74.027196 | E14: =IF(E15>0,E15/E13,"") -> 72.195594 | F14: =IF(F15>0,F15/F13,"") -> 55.225773 | G14: =IF(G15>0,G15/G13,"") -> 142.16205 | H14: =IF(H15>0,H15/H13,"") -> 103.61684 | I14: =IF(I15>0,I15/I13,"") -> 68.69933 | ... K14: =IF(K15>0,K15/K13,"") -> 81.499614 | L14: =IF(L13>0,L15/L13,0) -> 77.84428 | M14: =M25 -> 81.147234 | N14: =N25 -> 77.84428
A15: Price | B15: ='Data Sheet'!B90 -> 338.8 | C15: ='Data Sheet'!C90 -> 462.75 | D15: ='Data Sheet'!D90 -> 942.3 | E15: ='Data Sheet'!E90 -> 1141.85 | F15: ='Data Sheet'!F90 -> 933.7 | G15: ='Data Sheet'!G90 -> 1558.05 | H15: ='Data Sheet'!H90 -> 2536.15 | I15: ='Data Sheet'!I90 -> 2514.9 | ... K15: ='Data Sheet'!K90 -> 3063.35 | L15: ='Data Sheet'!B8 -> 4181.1 | M15: =M13*M14 -> 4263.4906 | N15: =N13*N14 -> 3859.8422
A17: RATIOS:
A18: Dividend Payout | B18: =IF('Data Sheet'!B30>0, 'Data Sheet'!B31/'Data Sheet'!B30, 0) -> 0.28956888 | C18: =IF('Data Sheet'!C30>0, 'Data Sheet'!C31/'Data Sheet'!C30, 0) -> 0.32444095 | D18: =IF('Data Sheet'!D30>0, 'Data Sheet'!D31/'Data Sheet'!D30, 0) -> 0.29459601 | E18: =IF('Data Sheet'!E30>0, 'Data Sheet'!E31/'Data Sheet'!E30, 0) -> 0.31613432 | F18: =IF('Data Sheet'!F30>0, 'Data Sheet'!F31/'Data Sheet'!F30, 0) -> 0.23717522 | G18: =IF('Data Sheet'!G30>0, 'Data Sheet'!G31/'Data Sheet'!G30, 0) -> 0.36587873 | H18: =IF('Data Sheet'!H30>0, 'Data Sheet'!H31/'Data Sheet'!H30, 0) -> 0.30717902 | I18: =IF('Data Sheet'!I30>0, 'Data Sheet'!I31/'Data Sheet'!I30, 0) -> 0.27384615 | ... K18: =IF('Data Sheet'!K30>0, 'Data Sheet'!K31/'Data Sheet'!K30, 0) -> 0.29337728
A19: OPM | B19: =IF(B6>0,B6/B4,0) -> 0.083304289 | C19: =IF(C6>0,C6/C4,0) -> 0.08776977 | D19: =IF(D6>0,D6/D4,0) -> 0.10199897 | E19: =IF(E6>0,E6/E4,0) -> 0.10080582 | F19: =IF(F6>0,F6/F4,0) -> 0.11699601 | G19: =IF(G6>0,G6/G4,0) -> 0.079698762 | H19: =IF(H6>0,H6/H4,0) -> 0.11611514 | I19: =IF(I6>0,I6/I4,0) -> 0.12032039 | ... L19: =IF(L6>0,L6/L4,0) -> 0.10525271
G22: TRENDS: | H22: 10 YEARS | I22: 7 YEARS | J22: 5 YEARS | K22: 3 YEARS | L22: RECENT | M22: BEST | N22: WORST
G23: Sales Growth | H23: =IF(B4=0,"",POWER($K4/B4,1/9)-1) -> 0.20512491 | I23: =IF(D4=0,"",POWER($K4/D4,1/7)-1) -> 0.20784585 | J23: =IF(F4=0,"",POWER($K4/F4,1/5)-1) -> 0.23489266 | K23: =IF(H4=0,"",POWER($K4/H4, 1/3)-1) -> 0.28042457 | L23: =IF(ISERROR(MAX(IF(J4=0,"",(K4-J4)/J4),IF(K4=0,"",(L4-K4)/K4))),"",MAX(IF(J4=0,"",(K4-J4)/J4),IF(K4=0,"",(L4-K4)/K4))) -> 0.25016541 | M23: =MAX(K23:L23) -> 0.28042457 | N23: =MIN(H23:L23) -> 0.20512491
G24: OPM | H24: =IF(SUM(B4:$K$4)=0,"",SUMPRODUCT(B19:$K$19,B4:$K$4)/SUM(B4:$K$4)) -> 0.10259367 | I24: =IF(SUM(E4:$K$4)=0,"",SUMPRODUCT(E19:$K$19,E4:$K$4)/SUM(E4:$K$4)) -> 0.10433438 | J24: =IF(SUM(G4:$K$4)=0,"",SUMPRODUCT(G19:$K$19,G4:$K$4)/SUM(G4:$K$4)) -> 0.10336299 | K24: =IF(SUM(I4:$K$4)=0, "", SUMPRODUCT(I19:$K$19,I4:$K$4)/SUM(I4:$K$4)) -> 0.10431581 | L24: =L19 -> 0.10525271 | M24: =MAX(K24:L24) -> 0.10525271 | N24: =MIN(H24:L24) -> 0.10259367
G25: Price to Earning | H25: =IF(ISERROR(AVERAGEIF(B14:$L14,">0")),"",AVERAGEIF(B14:$L14,">0")) -> 79.46844 | I25: =IF(ISERROR(AVERAGEIF(E14:$L14,">0")),"",AVERAGEIF(E14:$L14,">0")) -> 87.22365 | J25: =IF(ISERROR(AVERAGEIF(G14:$L14,">0")),"",AVERAGEIF(G14:$L14,">0")) -> 95.061305 | K25: =IF(ISERROR(AVERAGEIF(I14:$L14,">0")),"",AVERAGEIF(I14:$L14,">0")) -> 81.147234 | L25: =L14 -> 77.84428 | M25: =MAX(K25:L25) -> 81.147234 | N25: =MIN(H25:L25) -> 77.84428

Sheet Balance Sheet
A1: ='Profit & Loss '!A1 -> TITAN COMPANY LTD | E1: =UPDATE | J1: SCREENER.IN
A3: Narration | B3: ='Data Sheet'!B56 -> 42460 | C3: ='Data Sheet'!C56 -> 42825 | D3: ='Data Sheet'!D56 -> 43190 | E3: ='Data Sheet'!E56 -> 43555 | F3: ='Data Sheet'!F56 -> 43921 | G3: ='Data Sheet'!G56 -> 44286 | H3: ='Data Sheet'!H56 -> 44651 | I3: ='Data Sheet'!I56 -> 45016 | ... K3: ='Data Sheet'!K56 -> 45747
A4: Equity Share Capital | B4: ='Data Sheet'!B57 -> 88.78 | C4: ='Data Sheet'!C57 -> 88.78 | D4: ='Data Sheet'!D57 -> 88.78 | E4: ='Data Sheet'!E57 -> 88.78 | F4: ='Data Sheet'!F57 -> 89 | G4: ='Data Sheet'!G57 -> 89 | H4: ='Data Sheet'!H57 -> 89 | I4: ='Data Sheet'!I57 -> 89 | ... K4: ='Data Sheet'!K57 -> 89
A5: Reserves | B5: ='Data Sheet'!B58 -> 3417.5 | C5: ='Data Sheet'!C58 -> 4143.6 | D5: ='Data Sheet'!D58 -> 5001.1 | E5: ='Data Sheet'!E58 -> 5981.37 | F5: ='Data Sheet'!F58 -> 6580 | G5: ='Data Sheet'!G58 -> 7408 | H5: ='Data Sheet'!H58 -> 9214 | I5: ='Data Sheet'!I58 -> 11762 | ... K5: ='Data Sheet'!K58 -> 11535
A6: Borrowings | B6: ='Data Sheet'!B59 -> 113.05 | C6: ='Data Sheet'!C59 -> 1882.43 | D6: ='Data Sheet'!D59 -> 1691.01 | E6: ='Data Sheet'!E59 -> 2392.98 | F6: ='Data Sheet'!F59 -> 3562 | G6: ='Data Sheet'!G59 -> 5638 | H6: ='Data Sheet'!H59 -> 7275 | I6: ='Data Sheet'!I59 -> 9367 | ... K6: ='Data Sheet'!K59 -> 20777
A7: Other Liabilities | B7: ='Data Sheet'!B60 -> 2722.58 | C7: ='Data Sheet'!C60 -> 2292.76 | D7: ='Data Sheet'!D60 -> 2740.15 | E7: ='Data Sheet'!E60 -> 3246.71 | F7: ='Data Sheet'!F60 -> 3313 | G7: ='Data Sheet'!G60 -> 3309 | H7: ='Data Sheet'!H60 -> 4610 | I7: ='Data Sheet'!I60 -> 5802 | ... K7: ='Data Sheet'!K60 -> 8244
A8: Total | B8: ='Data Sheet'!B61 -> 6341.91 | C8: ='Data Sheet'!C61 -> 8407.57 | D8: ='Data Sheet'!D61 -> 9521.04 | E8: ='Data Sheet'!E61 -> 11709.84 | F8: ='Data Sheet'!F61 -> 13544 | G8: ='Data Sheet'!G61 -> 16444 | H8: ='Data Sheet'!H61 -> 21188 | I8: ='Data Sheet'!I61 -> 27020 | ... K8: ='Data Sheet'!K61 -> 40645
A10: Net Block | B10: ='Data Sheet'!B62 -> 770.54 | C10: ='Data Sheet'!C62 -> 1188.72 | D10: ='Data Sheet'!D62 -> 1473.81 | E10: ='Data Sheet'!E62 -> 1566.63 | F10: ='Data Sheet'!F62 -> 2633 | G10: ='Data Sheet'!G62 -> 2523 | H10: ='Data Sheet'!H62 -> 2544 | I10: ='Data Sheet'!I62 -> 2998 | ... K10: ='Data Sheet'!K62 -> 4062
A11: Capital Work in Progress | B11: ='Data Sheet'!B63 -> 106.71 | C11: ='Data Sheet'!C63 -> 152.07 | D11: ='Data Sheet'!D63 -> 43.37 | E11: ='Data Sheet'!E63 -> 31.77 | F11: ='Data Sheet'!F63 -> 18 | G11: ='Data Sheet'!G63 -> 32 | H11: ='Data Sheet'!H63 -> 85 | I11: ='Data Sheet'!I63 -> 144 | ... K11: ='Data Sheet'!K63 -> 105
A12: Investments | B12: ='Data Sheet'!B64 -> 30.41 | C12: ='Data Sheet'!C64 -> 430.73 | D12: ='Data Sheet'!D64 -> 35.99 | E12: ='Data Sheet'!E64 -> 108.42 | F12: ='Data Sheet'!F64 -> 158 | G12: ='Data Sheet'!G64 -> 2824 | H12: ='Data Sheet'!H64 -> 294 | I12: ='Data Sheet'!I64 -> 2515 | ... K12: ='Data Sheet'!K64 -> 1988
A13: Other Assets | B13: ='Data Sheet'!B65 -> 5434.25 | C13: ='Data Sheet'!C65 -> 6636.05 | D13: ='Data Sheet'!D65 -> 7967.87 | E13: ='Data Sheet'!E65 -> 10003.02 | F13: ='Data Sheet'!F65 -> 10735 | G13: ='Data Sheet'!G65 -> 11065 | H13: ='Data Sheet'!H65 -> 18265 | I13: ='Data Sheet'!I65 -> 21363 | ... K13: ='Data Sheet'!K65 -> 34490
A14: Total | B14: ='Data Sheet'!B66 -> 6341.91 | C14: ='Data Sheet'!C66 -> 8407.57 | D14: ='Data Sheet'!D66 -> 9521.04 | E14: ='Data Sheet'!E66 -> 11709.84 | F14: ='Data Sheet'!F66 -> 13544 | G14: ='Data Sheet'!G66 -> 16444 | H14: ='Data Sheet'!H66 -> 21188 | I14: ='Data Sheet'!I66 -> 27020 | ... K14: ='Data Sheet'!K66 -> 40645
A16: Working Capital | B16: =B13-B7 -> 2711.67 | C16: =C13-C7 -> 4343.29 | D16: =D13-D7 -> 5227.72 | E16: =E13-E7 -> 6756.31 | F16: =F13-F7 -> 7422 | G16: =G13-G7 -> 7756 | H16: =H13-H7 -> 13655 | I16: =I13-I7 -> 15561 | ... K16: =K13-K7 -> 26246
A17: Debtors | B17: ='Data Sheet'!B67 -> 192.5 | C17: ='Data Sheet'!C67 -> 207.6 | D17: ='Data Sheet'!D67 -> 295.69 | E17: ='Data Sheet'!E67 -> 420.45 | F17: ='Data Sheet'!F67 -> 312 | G17: ='Data Sheet'!G67 -> 366 | H17: ='Data Sheet'!H67 -> 565 | I17: ='Data Sheet'!I67 -> 674 | ... K17: ='Data Sheet'!K67 -> 1068
A18: Inventory | B18: ='Data Sheet'!B68 -> 4447.15 | C18: ='Data Sheet'!C68 -> 4925.74 | D18: ='Data Sheet'!D68 -> 5924.84 | E18: ='Data Sheet'!E68 -> 7038.82 | F18: ='Data Sheet'!F68 -> 8103 | G18: ='Data Sheet'!G68 -> 8408 | H18: ='Data Sheet'!H68 -> 13609 | I18: ='Data Sheet'!I68 -> 16584 | ... K18: ='Data Sheet'!K68 -> 28184
A20: Debtor Days | B20: =IF('Profit & Loss '!B4>0,'Balance Sheet'!B17/('Profit & Loss '!B4/365),0) -> 6.2312155 | C20: =IF('Profit & Loss '!C4>0,'Balance Sheet'!C17/('Profit & Loss '!C4/365),0) -> 5.714122 | D20: =IF('Profit & Loss '!D4>0,'Balance Sheet'!D17/('Profit & Loss '!D4/365),0) -> 6.6953095 | E20: =IF('Profit & Loss '!E4>0,'Balance Sheet'!E17/('Profit & Loss '!E4/365),0) -> 7.7591372 | F20: =IF('Profit & Loss '!F4>0,'Balance Sheet'!F17/('Profit & Loss '!F4/365),0) -> 5.4094623 | G20: =IF('Profit & Loss '!G4>0,'Balance Sheet'!G17/('Profit & Loss '!G4/365),0) -> 6.1721493 | H20: =IF('Profit & Loss '!H4>0,'Balance Sheet'!H17/('Profit & Loss '!H4/365),0) -> 7.1608389 | I20: =IF('Profit & Loss '!I4>0,'Balance Sheet'!I17/('Profit & Loss '!I4/365),0) -> 6.063093 | ... K20: =IF('Profit & Loss '!K4>0,'Balance Sheet'!K17/('Profit & Loss '!K4/365),0) -> 6.4479952
A21: Inventory Turnover | B21: =IF('Balance Sheet'!B18>0,'Profit & Loss '!B4/'Balance Sheet'!B18,0) -> 2.5355317 | C21: =IF('Balance Sheet'!C18>0,'Profit & Loss '!C4/'Balance Sheet'!C18,0) -> 2.6921498 | D21: =IF('Balance Sheet'!D18>0,'Profit & Loss '!D4/'Balance Sheet'!D18,0) -> 2.7207098 | E21: =IF('Balance Sheet'!E18>0,'Profit & Loss '!E4/'Balance Sheet'!E18,0) -> 2.8099198 | F21: =IF('Balance Sheet'!F18>0,'Profit & Loss '!F4/'Balance Sheet'!F18,0) -> 2.5980501 | G21: =IF('Balance Sheet'!G18>0,'Profit & Loss '!G4/'Balance Sheet'!G18,0) -> 2.574215 | H21: =IF('Balance Sheet'!H18>0,'Profit & Loss '!H4/'Balance Sheet'!H18,0) -> 2.1161731 | I21: =IF('Balance Sheet'!I18>0,'Profit & Loss '!I4/'Balance Sheet'!I18,0) -> 2.4466353 | ... K21: =IF('Balance Sheet'!K18>0,'Profit & Loss '!K4/'Balance Sheet'!K18,0) -> 2.1450468
A23: Return on Equity | B23: =IF(SUM('Balance Sheet'!B4:B5)>0,'Profit & Loss '!B12/SUM('Balance Sheet'!B4:B5),"") -> 0.19237482 | C23: =IF(SUM('Balance Sheet'!C4:C5)>0,'Profit & Loss '!C12/SUM('Balance Sheet'!C4:C5),"") -> 0.16810164 | D23: =IF(SUM('Balance Sheet'!D4:D5)>0,'Profit & Loss '!D12/SUM('Balance Sheet'!D4:D5),"") -> 0.22202685 | E23: =IF(SUM('Balance Sheet'!E4:E5)>0,'Profit & Loss '!E12/SUM('Balance Sheet'!E4:E5),"") -> 0.23132048 | F23: =IF(SUM('Balance Sheet'!F4:F5)>0,'Profit & Loss '!F12/SUM('Balance Sheet'!F4:F5),"") -> 0.22507123 | G23: =IF(SUM('Balance Sheet'!G4:G5)>0,'Profit & Loss '!G12/SUM('Balance Sheet'!G4:G5),"") -> 0.12978525 | H23: =IF(SUM('Balance Sheet'!H4:H5)>0,'Profit & Loss '!H12/SUM('Balance Sheet'!H4:H5),"") -> 0.23358057 | I23: =IF(SUM('Balance Sheet'!I4:I5)>0,'Profit & Loss '!I12/SUM('Balance Sheet'!I4:I5),"") -> 0.27423846 | ... K23: =IF(SUM('Balance Sheet'!K4:K5)>0,'Profit & Loss '!K12/SUM('Balance Sheet'!K4:K5),"") -> 0.28707846
A24: Return on Capital Emp | C24: =IF((B4+B5+B6+C4+C5+C6)>0,('Profit & Loss '!C10+'Profit & Loss '!C9)*2/(B4+B5+B6+C4+C5+C6),"") -> 0.20772046 | D24: =IF((C4+C5+C6+D4+D5+D6)>0,('Profit & Loss '!D10+'Profit & Loss '!D9)*2/(C4+C5+C6+D4+D5+D6),"") -> 0.24546167 | E24: =IF((D4+D5+D6+E4+E5+E6)>0,('Profit & Loss '!E10+'Profit & Loss '!E9)*2/(D4+D5+D6+E4+E5+E6),"") -> 0.26363518 | F24: =IF((E4+E5+E6+F4+F5+F6)>0,('Profit & Loss '!F10+'Profit & Loss '!F9)*2/(E4+E5+E6+F4+F5+F6),"") -> 0.24264301 | G24: =IF((F4+F5+F6+G4+G5+G6)>0,('Profit & Loss '!G10+'Profit & Loss '!G9)*2/(F4+F5+F6+G4+G5+G6),"") -> 0.13095951 | H24: =IF((G4+G5+G6+H4+H5+H6)>0,('Profit & Loss '!H10+'Profit & Loss '!H9)*2/(G4+G5+G6+H4+H5+H6),"") -> 0.21014371 | I24: =IF((H4+H5+H6+I4+I5+I6)>0,('Profit & Loss '!I10+'Profit & Loss '!I9)*2/(H4+H5+H6+I4+I5+I6),"") -> 0.2511906 | J24: =IF((I4+I5+I6+J4+J5+J6)>0,('Profit & Loss '!J10+'Profit & Loss '!J9)*2/(I4+I5+I6+J4+J5+J6),"") -> 0.22722642 | K24: =IF((J4+J5+J6+K4+K5+K6)>0,('Profit & Loss '!K10+'Profit & Loss '!K9)*2/(J4+J5+J6+K4+K5+K6),"") -> 0.19147971

Sheet Cash Flow 
A1: ='Balance Sheet'!A1 -> TITAN COMPANY LTD | E1: =UPDATE | J1: SCREENER.IN
A3: Narration | B3: ='Data Sheet'!B81 -> 42460 | C3: ='Data Sheet'!C81 -> 42825 | D3: ='Data Sheet'!D81 -> 43190 | E3: ='Data Sheet'!E81 -> 43555 | F3: ='Data Sheet'!F81 -> 43921 | G3: ='Data Sheet'!G81 -> 44286 | H3: ='Data Sheet'!H81 -> 44651 | I3: ='Data Sheet'!I81 -> 45016 | ... K3: ='Data Sheet'!K81 -> 45747
A4: Cash from Operating Activity | B4: ='Data Sheet'!B82 -> 576.09 | C4: ='Data Sheet'!C82 -> 1712.3 | D4: ='Data Sheet'!D82 -> -51.12 | E4: ='Data Sheet'!E82 -> 1242.92 | F4: ='Data Sheet'!F82 -> -348 | G4: ='Data Sheet'!G82 -> 4139 | H4: ='Data Sheet'!H82 -> -724 | I4: ='Data Sheet'!I82 -> 1370 | ... K4: ='Data Sheet'!K82 -> -541
A5: Cash from Investing Activity | B5: ='Data Sheet'!B83 -> -158.79 | C5: ='Data Sheet'!C83 -> -953.15 | D5: ='Data Sheet'!D83 -> 97.62 | E5: ='Data Sheet'!E83 -> -796.61 | F5: ='Data Sheet'!F83 -> 235 | G5: ='Data Sheet'!G83 -> -2799 | H5: ='Data Sheet'!H83 -> 1165 | I5: ='Data Sheet'!I83 -> -1814 | ... K5: ='Data Sheet'!K83 -> 546
A6: Cash from Financing Activity | B6: ='Data Sheet'!B84 -> -504.84 | C6: ='Data Sheet'!C84 -> -165.6 | D6: ='Data Sheet'!D84 -> -252.45 | E6: ='Data Sheet'!E84 -> -488.83 | F6: ='Data Sheet'!F84 -> -242 | G6: ='Data Sheet'!G84 -> -1234 | H6: ='Data Sheet'!H84 -> -403 | I6: ='Data Sheet'!I84 -> 457 | ... K6: ='Data Sheet'!K84 -> -7
A7: Net Cash Flow | B7: ='Data Sheet'!B85 -> -87.54 | C7: ='Data Sheet'!C85 -> 593.55 | D7: ='Data Sheet'!D85 -> -205.95 | E7: ='Data Sheet'!E85 -> -42.52 | F7: ='Data Sheet'!F85 -> -355 | G7: ='Data Sheet'!G85 -> 106 | H7: ='Data Sheet'!H85 -> 38 | I7: ='Data Sheet'!I85 -> 13 | ... K7: ='Data Sheet'!K85 -> -2

Sheet Quarters
A1: ='Profit & Loss '!A1 -> TITAN COMPANY LTD | E1: =UPDATE | J1: SCREENER.IN
A3: Narration | B3: ='Data Sheet'!B41 -> 45199 | C3: ='Data Sheet'!C41 -> 45291 | D3: ='Data Sheet'!D41 -> 45382 | E3: ='Data Sheet'!E41 -> 45473 | F3: ='Data Sheet'!F41 -> 45565 | G3: ='Data Sheet'!G41 -> 45657 | H3: ='Data Sheet'!H41 -> 45747 | I3: ='Data Sheet'!I41 -> 45838 | ... K3: ='Data Sheet'!K41 -> 46022
A4: Sales | B4: ='Data Sheet'!B42 -> 12529 | C4: ='Data Sheet'!C42 -> 14164 | D4: ='Data Sheet'!D42 -> 12494 | E4: ='Data Sheet'!E42 -> 13266 | F4: ='Data Sheet'!F42 -> 14534 | G4: ='Data Sheet'!G42 -> 17740 | H4: ='Data Sheet'!H42 -> 14916 | I4: ='Data Sheet'!I42 -> 16523 | ... K4: ='Data Sheet'!K42 -> 25416
A5: Expenses | B5: ='Data Sheet'!B43 -> 11118 | C5: ='Data Sheet'!C43 -> 12599 | D5: ='Data Sheet'!D43 -> 11303 | E5: ='Data Sheet'!E43 -> 12019 | F5: ='Data Sheet'!F43 -> 13298 | G5: ='Data Sheet'!G43 -> 16066 | H5: ='Data Sheet'!H43 -> 13379 | I5: ='Data Sheet'!I43 -> 14693 | ... K5: ='Data Sheet'!K43 -> 22703
A6: Operating Profit | B6: ='Data Sheet'!B50 -> 1411 | C6: ='Data Sheet'!C50 -> 1565 | D6: ='Data Sheet'!D50 -> 1191 | E6: ='Data Sheet'!E50 -> 1247 | F6: ='Data Sheet'!F50 -> 1236 | G6: ='Data Sheet'!G50 -> 1674 | H6: ='Data Sheet'!H50 -> 1537 | I6: ='Data Sheet'!I50 -> 1830 | ... K6: ='Data Sheet'!K50 -> 2713
A7: Other Income | B7: ='Data Sheet'!B44 -> 125 | C7: ='Data Sheet'!C44 -> 136 | D7: ='Data Sheet'!D44 -> 159 | E7: ='Data Sheet'!E44 -> 120 | F7: ='Data Sheet'!F44 -> 123 | G7: ='Data Sheet'!G44 -> 128 | H7: ='Data Sheet'!H44 -> 116 | I7: ='Data Sheet'!I44 -> 105 | ... K7: ='Data Sheet'!K44 -> -1
A8: Depreciation | B8: ='Data Sheet'!B45 -> 144 | C8: ='Data Sheet'!C45 -> 154 | D8: ='Data Sheet'!D45 -> 158 | E8: ='Data Sheet'!E45 -> 164 | F8: ='Data Sheet'!F45 -> 171 | G8: ='Data Sheet'!G45 -> 175 | H8: ='Data Sheet'!H45 -> 183 | I8: ='Data Sheet'!I45 -> 184 | ... K8: ='Data Sheet'!K45 -> 207
A9: Interest | B9: ='Data Sheet'!B46 -> 140 | C9: ='Data Sheet'!C46 -> 169 | D9: ='Data Sheet'!D46 -> 201 | E9: ='Data Sheet'!E46 -> 230 | F9: ='Data Sheet'!F46 -> 240 | G9: ='Data Sheet'!G46 -> 231 | H9: ='Data Sheet'!H46 -> 252 | I9: ='Data Sheet'!I46 -> 271 | ... K9: ='Data Sheet'!K46 -> 282
A10: Profit before tax | B10: ='Data Sheet'!B47 -> 1252 | C10: ='Data Sheet'!C47 -> 1378 | D10: ='Data Sheet'!D47 -> 991 | E10: ='Data Sheet'!E47 -> 973 | F10: ='Data Sheet'!F47 -> 948 | G10: ='Data Sheet'!G47 -> 1396 | H10: ='Data Sheet'!H47 -> 1218 | I10: ='Data Sheet'!I47 -> 1480 | ... K10: ='Data Sheet'!K47 -> 2223
A11: Tax | B11: ='Data Sheet'!B48 -> 336 | C11: ='Data Sheet'!C48 -> 325 | D11: ='Data Sheet'!D48 -> 220 | E11: ='Data Sheet'!E48 -> 258 | F11: ='Data Sheet'!F48 -> 244 | G11: ='Data Sheet'!G48 -> 349 | H11: ='Data Sheet'!H48 -> 347 | I11: ='Data Sheet'!I48 -> 389 | ... K11: ='Data Sheet'!K48 -> 539
A12: Net profit | B12: ='Data Sheet'!B49 -> 915 | C12: ='Data Sheet'!C49 -> 1053 | D12: ='Data Sheet'!D49 -> 771 | E12: ='Data Sheet'!E49 -> 715 | F12: ='Data Sheet'!F49 -> 704 | G12: ='Data Sheet'!G49 -> 1047 | H12: ='Data Sheet'!H49 -> 871 | I12: ='Data Sheet'!I49 -> 1091 | ... K12: ='Data Sheet'!K49 -> 1684
A14: OPM | B14: =IF(B4>0,B6/B4,"") -> 0.11261872 | C14: =IF(C4>0,C6/C4,"") -> 0.11049139 | D14: =IF(D4>0,D6/D4,"") -> 0.095325756 | E14: =IF(E4>0,E6/E4,"") -> 0.093999698 | F14: =IF(F4>0,F6/F4,"") -> 0.085041971 | G14: =IF(G4>0,G6/G4,"") -> 0.094363021 | H14: =IF(H4>0,H6/H4,"") -> 0.10304371 | I14: =IF(I4>0,I6/I4,"") -> 0.11075471 | ... K14: =IF(K4>0,K6/K4,"") -> 0.10674378
